<html>
  <head>
    <meta charset="utf-8">
    <meta name="viewport" content="width=device-width, initial-scale=1, shrink-to-fit=no">
    <link rel="stylesheet" href="https://stackpath.bootstrapcdn.com/bootstrap/4.3.1/css/bootstrap.min.css" integrity="sha384-ggOyR0iXCbMQv3Xipma34MD+dH/1fQ784/j6cY/iJTQUOhcWr7x9JvoRxT2MZw1T" crossorigin="anonymous">
    <script src="https://cdn.plot.ly/plotly-latest.min.js"></script>
    <script type="text/javascript">
      window.PlotlyConfig = { MathJaxConfig: "local" };
    </script>
  </head>
  <body>
    <div class="container-fluid p-3" id="root"><div><div class="row"><div class="col"><h4>clock_clock_error.1.ciar33kuken57n0grallurrcu</h4></div></div><div class="row mt-2"><div class="col"><div class="alert alert-warning">The task was shut down prematurely (before the stack was manually stopped)</div></div></div><div class="row mt-2"><div class="col"><div class="alert alert-danger">It seems there was an error during the task execution</div></div></div><div class="row mt-2"><div class="col"><div class="card"><div class="card-body"><h5 class="card-title">Task details</h5><dl class="row mb-0"><dt class="col-sm-3 text-muted">Desired state</dt><dd class="col-sm-9">shutdown</dd><dt class="col-sm-3 text-muted">Node ID</dt><dd class="col-sm-9"><code>xcz6py8flzqz9wzlnqflbq5ol</code></dd><dt class="col-sm-3 text-muted">Service ID</dt><dd class="col-sm-9"><code>ufxv5z59nic1jz2z31exsttp5</code></dd><dt class="col-sm-3 text-muted">Task ID</dt><dd class="col-sm-9"><code>ciar33kuken57n0grallurrcu</code></dd><dt class="col-sm-3 text-muted">Container ID</dt><dd class="col-sm-9"><code>ab4d30bf43fef7224b815e4e98f48f7b4e13d27deef929727db2a672d8a129c1</code></dd><dt class="col-sm-3 text-muted">Created at</dt><dd class="col-sm-9">2020-12-16T10:12:25.119825+00:00</dd><dt class="col-sm-3 text-muted">Updated at</dt><dd class="col-sm-9">2020-12-16T10:12:44.574023+00:00</dd><dt class="col-sm-3 text-muted">Started at</dt><dd class="col-sm-9">2020-12-16T10:12:42.939173+00:00</dd></dl></div></div></div></div><div class="row mt-2"><div class="col"><div class="row"></div></div></div><div class="row mt-2"><div class="col"><div class="card"><div class="card-body small bg-danger text-white"><h5 class="card-title">Logs</h5><h6 class="card-subtitle mb-2 ">Snapshot of the most recent log entries</h6><pre class="mb-0 text-light">clock_clock_error.1.ciar33kuken5@manager1    |            'node': 'clock_clock_error.1.ciar33kuken57n0grallurrcu',
clock_clock_error.1.ciar33kuken5@manager1    |            'processor': 'x86_64',
clock_clock_error.1.ciar33kuken5@manager1    |            'release': '4.15.0-121-generic',
clock_clock_error.1.ciar33kuken5@manager1    |            'system': 'Linux',
clock_clock_error.1.ciar33kuken5@manager1    |            'version': '#123-Ubuntu SMP Mon Oct 5 16:16:40 UTC 2020'}}
clock_clock_error.1.ciar33kuken5@manager1    | 2020-12-16 10:12:42 clock_clock_error.1.ciar33kuken57n0grallurrcu wotemu.cli.app[1] ERROR WoT app error: Exception('Error raised at 2020-12-16 10:12:42.940546 UTC')
clock_clock_error.1.ciar33kuken5@manager1    | 2020-12-16 10:12:42 clock_clock_error.1.ciar33kuken57n0grallurrcu wotemu.cli.app[1] INFO Cancelling WoT app task: &lt;Task finished name='Task-4' coro=&lt;app() done, defined at /root/wotemu/examples/app/error.py:9&gt; exception=Exception('Error raised at 2020-12-16 10:12:42.940546 UTC')&gt;
clock_clock_error.1.ciar33kuken5@manager1    | 2020-12-16 10:12:42 clock_clock_error.1.ciar33kuken57n0grallurrcu wotemu.cli.app[1] WARNING Error during WoT app cancelation
clock_clock_error.1.ciar33kuken5@manager1    | Traceback (most recent call last):
clock_clock_error.1.ciar33kuken5@manager1    |   File "/usr/local/lib/python3.8/dist-packages/wotemu/cli/app.py", line 132, in _stop
clock_clock_error.1.ciar33kuken5@manager1    |     await asyncio.wait_for(app_task, _TIMEOUT)
clock_clock_error.1.ciar33kuken5@manager1    |   File "/usr/lib/python3.8/asyncio/tasks.py", line 483, in wait_for
clock_clock_error.1.ciar33kuken5@manager1    |     return fut.result()
clock_clock_error.1.ciar33kuken5@manager1    |   File "/root/wotemu/examples/app/error.py", line 19, in app
clock_clock_error.1.ciar33kuken5@manager1    |     raise Exception(f"Error raised at {now} UTC")
clock_clock_error.1.ciar33kuken5@manager1    | Exception: Error raised at 2020-12-16 10:12:42.940546 UTC
clock_clock_error.1.ciar33kuken5@manager1    | 2020-12-16 10:12:42 clock_clock_error.1.ciar33kuken57n0grallurrcu wotemu.cli.app[1] DEBUG Shutting down Servient: &lt;wotpy.wot.servient.Servient object at 0x7f5276248b80&gt;
clock_clock_error.1.ciar33kuken5@manager1    | 2020-12-16 10:12:42 clock_clock_error.1.ciar33kuken57n0grallurrcu wotemu.monitor.base[1] DEBUG Stopping node monitor
clock_clock_error.1.ciar33kuken5@manager1    | 2020-12-16 10:12:42 clock_clock_error.1.ciar33kuken57n0grallurrcu wotemu.utils[1] DEBUG /usr/bin/cgget -v -r cpuacct.usage /: b'/:\n3910683290\n\n'
clock_clock_error.1.ciar33kuken5@manager1    | 2020-12-16 10:12:42 clock_clock_error.1.ciar33kuken57n0grallurrcu wotemu.monitor.packet[1] DEBUG Starting LiveCapture on interface eth0 with display filter: tcp.port==1883 or tcp.port==80 or tcp.port==81 or tcp.port==5683 or udp.port==5683
clock_clock_error.1.ciar33kuken5@manager1    | 2020-12-16 10:12:42 clock_clock_error.1.ciar33kuken57n0grallurrcu wotemu.monitor.base[1] DEBUG Closed Redis connection
clock_clock_error.1.ciar33kuken5@manager1    | 2020-12-16 10:12:42 clock_clock_error.1.ciar33kuken57n0grallurrcu wotemu.cli.app[1] DEBUG Closing Redis
clock_clock_error.1.ciar33kuken5@manager1    | 2020-12-16 10:12:42 clock_clock_error.1.ciar33kuken57n0grallurrcu wotemu.cli.app[1] DEBUG Stopping loop
clock_clock_error.1.ciar33kuken5@manager1    | 2020-12-16 10:12:42 clock_clock_error.1.ciar33kuken57n0grallurrcu wotemu.cli.app[1] DEBUG Closing loop
clock_clock_error.1.ciar33kuken5@manager1    | 2020-12-16 10:12:42 clock_clock_error.1.ciar33kuken57n0grallurrcu wotemu.cli.app[1] WARNING Exiting with code: 1
clock_clock_error.1.ciar33kuken5@manager1    | Traceback (most recent call last):
clock_clock_error.1.ciar33kuken5@manager1    |   File "&lt;string&gt;", line 1, in &lt;module&gt;
clock_clock_error.1.ciar33kuken5@manager1    |   File "/usr/lib/python3.8/multiprocessing/spawn.py", line 116, in spawn_main
clock_clock_error.1.ciar33kuken5@manager1    |     exitcode = _main(fd, parent_sentinel)
clock_clock_error.1.ciar33kuken5@manager1    |   File "/usr/lib/python3.8/multiprocessing/spawn.py", line 126, in _main
clock_clock_error.1.ciar33kuken5@manager1    |     self = reduction.pickle.load(from_parent)
clock_clock_error.1.ciar33kuken5@manager1    |   File "/usr/lib/python3.8/multiprocessing/synchronize.py", line 110, in __setstate__
clock_clock_error.1.ciar33kuken5@manager1    |     self._semlock = _multiprocessing.SemLock._rebuild(*state)
clock_clock_error.1.ciar33kuken5@manager1    | FileNotFoundError: [Errno 2] No such file or directory
clock_clock_error.1.ciar33kuken5@manager1    | 2020-12-16 10:12:43 clock_clock_error.1.ciar33kuken57n0grallurrcu wotemu.cli.app[1] DEBUG Exception in loop:
clock_clock_error.1.ciar33kuken5@manager1    | {'message': 'Task was destroyed but it is pending!',
clock_clock_error.1.ciar33kuken5@manager1    |  'task': &lt;Task pending name='Task-10' coro=&lt;monitor_system() running at /usr/local/lib/python3.8/dist-packages/wotemu/monitor/system.py:193&gt; wait_for=&lt;Future pending cb=[&lt;TaskWakeupMethWrapper object at 0x7f5276179b50&gt;()]&gt;&gt;}
clock_clock_error.1.ciar33kuken5@manager1    | 2020-12-16 10:12:43 clock_clock_error.1.ciar33kuken57n0grallurrcu wotemu.cli.app[1] DEBUG Exception in loop:
clock_clock_error.1.ciar33kuken5@manager1    | {'message': 'Task was destroyed but it is pending!',
clock_clock_error.1.ciar33kuken5@manager1    |  'task': &lt;Task pending name='Task-11' coro=&lt;monitor_packets() running at /usr/local/lib/python3.8/dist-packages/wotemu/monitor/packet.py:232&gt; wait_for=&lt;Future pending cb=[&lt;TaskWakeupMethWrapper object at 0x7f52760e0dc0&gt;()]&gt;&gt;}</pre></div></div></div></div></div></div>
  </body>
</html>